<?xml version="1.0"?>
<robot name="wx250s">
  <material name="interbotix_black">
    <texture filename="package://wx250s/meshes/interbotix_black.png"/>
  </material>

  <link name="base_link">
    <visual>
      <origin xyz="0 0 0" rpy="0 0 1.57079632679"/>
      <geometry>
        <mesh filename="package://wx250s/meshes/wx250s_meshes/wx250s_1_base.stl" scale="0.001 0.001 0.001"/>
      </geometry>
      <material name="interbotix_black"/>
    </visual>
    <collision>
      <origin xyz="0 0 0" rpy="0 0 1.57079632679"/>
      <geometry>
        <mesh filename="package://wx250s/meshes/wx250s_meshes/wx250s_1_base.stl" scale="0.001 0.001 0.001"/>
      </geometry>
    </collision>
    <inertial>
      <origin xyz="-0.0380446 0.000613892 0.0193354" rpy="0 0 1.57079632679"/>
      <mass value="0.538736"/>
      <inertia ixx="0.002115" iyy="0.0006921" izz="0.002524" ixy="-0.00001635" ixz="0.0000006998" iyz="0.00004642"/>
    </inertial>
  </link>

  <joint name="waist" type="revolute">
    <parent link="base_link"/>
    <child link="shoulder_link"/>
    <origin xyz="0 0 0.072" rpy="0 0 0"/>
    <axis xyz="0 0 1"/>
    <limit lower="-3.14158265359" upper="3.14158265359" effort="10" velocity="3.14159265359"/>
    <dynamics friction="0.1"/>
  </joint>

  <link name="shoulder_link">
    <visual>
      <origin xyz="0 0 -0.003" rpy="0 0 1.57079632679"/>
      <geometry>
        <mesh filename="package://wx250s/meshes/wx250s_meshes/wx250s_2_shoulder.stl" scale="0.001 0.001 0.001"/>
      </geometry>
      <material name="interbotix_black"/>
    </visual>
    <collision>
      <origin xyz="0 0 -0.003" rpy="0 0 1.57079632679"/>
      <geometry>
        <mesh filename="package://wx250s/meshes/wx250s_meshes/wx250s_2_shoulder.stl" scale="0.001 0.001 0.001"/>
      </geometry>
    </collision>
    <inertial>
      <origin xyz="0.0000223482 0.0000414609 0.0066287" rpy="0 0 1.57079632679"/>
      <mass value="0.480879"/>
      <inertia ixx="0.000379" iyy="0.0005557" izz="0.0005889" ixy="0.0000000022" ixz="-0.0000003561" iyz="0.0000012245"/>
    </inertial>
  </link>

  <joint name="shoulder" type="revolute">
    <parent link="shoulder_link"/>
    <child link="upper_arm_link"/>
    <origin xyz="0 0 0.03865" rpy="0 0 0"/>
    <axis xyz="0 1 0"/>
    <limit lower="-1.88495559215" upper="1.98967534727" effort="20" velocity="3.14159265359"/>
    <dynamics friction="0.1"/>
  </joint>

  <link name="upper_arm_link">
    <visual>
      <origin xyz="0 0 0" rpy="0 0 1.57079632679"/>
      <geometry>
        <mesh filename="package://wx250s/meshes/wx250s_meshes/wx250s_3_upper_arm.stl" scale="0.001 0.001 0.001"/>
      </geometry>
      <material name="interbotix_black"/>
    </visual>
    <collision>
      <origin xyz="0 0 0" rpy="0 0 1.57079632679"/>
      <geometry>
        <mesh filename="package://wx250s/meshes/wx250s_meshes/wx250s_3_upper_arm.stl" scale="0.001 0.001 0.001"/>
      </geometry>
    </collision>
    <inertial>
      <origin xyz="0.0171605 0.0000002725 0.191323" rpy="0 0 1.57079632679"/>
      <mass value="0.430811"/>
      <inertia ixx="0.003463" iyy="0.003587" izz="0.0004566" ixy="-0.0000000001" ixz="-0.0000000002" iyz="0.0004272"/>
    </inertial>
  </link>

  <joint name="elbow" type="revolute">
    <parent link="upper_arm_link"/>
    <child link="upper_forearm_link"/>
    <origin xyz="0.04975 0 0.25" rpy="0 0 0"/>
    <axis xyz="0 1 0"/>
    <limit lower="-2.14675497995" upper="1.60570291183" effort="15" velocity="3.14159265359"/>
    <dynamics friction="0.1"/>
  </joint>

  <link name="upper_forearm_link">
    <visual>
      <origin xyz="0 0 0" rpy="0 0 0"/>
      <geometry>
        <mesh filename="package://wx250s/meshes/wx250s_meshes/wx250s_4_upper_forearm.stl" scale="0.001 0.001 0.001"/>
      </geometry>
      <material name="interbotix_black"/>
    </visual>
    <collision>
      <origin xyz="0 0 0" rpy="0 0 0"/>
      <geometry>
        <mesh filename="package://wx250s/meshes/wx250s_meshes/wx250s_4_upper_forearm.stl" scale="0.001 0.001 0.001"/>
      </geometry>
    </collision>
    <inertial>
      <origin xyz="0.107963 0.000115876 0" rpy="0 0 0"/>
      <mass value="0.234589"/>
      <inertia ixx="0.00003971" iyy="0.0008878" izz="0.000888" ixy="0.0000023528" ixz="0" iyz="0"/>
    </inertial>
  </link>

  <joint name="forearm_roll" type="revolute">
    <parent link="upper_forearm_link"/>
    <child link="lower_forearm_link"/>
    <origin xyz="0.175 0 0" rpy="0 0 0"/>
    <axis xyz="1 0 0"/>
    <limit lower="-3.14158265359" upper="3.14158265359" effort="2" velocity="3.14159265359"/>
    <dynamics friction="0.1"/>
  </joint>

  <link name="lower_forearm_link">
    <visual>
      <origin xyz="0 0 0" rpy="3.14159265359 0 0"/>
      <geometry>
        <mesh filename="package://wx250s/meshes/wx250s_meshes/wx250s_5_lower_forearm.stl" scale="0.001 0.001 0.001"/>
      </geometry>
      <material name="interbotix_black"/>
    </visual>
    <collision>
      <origin xyz="0 0 0" rpy="3.14159265359 0 0"/>
      <geometry>
        <mesh filename="package://wx250s/meshes/wx250s_meshes/wx250s_5_lower_forearm.stl" scale="0.001 0.001 0.001"/>
      </geometry>
    </collision>
    <inertial>
      <origin xyz="0.0374395 0.00522252 0" rpy="3.14159265359 0 0"/>
      <mass value="0.220991"/>
      <inertia ixx="0.00006369" iyy="0.0001677" izz="0.0001834" ixy="-0.00002292" ixz="0" iyz="0"/>
    </inertial>
  </link>

  <joint name="wrist_angle" type="revolute">
    <parent link="lower_forearm_link"/>
    <child link="wrist_link"/>
    <origin xyz="0.075 0 0" rpy="0 0 0"/>
    <axis xyz="0 1 0"/>
    <limit lower="-1.74532925199" upper="2.14675497995" effort="5" velocity="3.14159265359"/>
    <dynamics friction="0.1"/>
  </joint>

  <link name="wrist_link">
    <visual>
      <origin xyz="0 0 0" rpy="0 0 1.57079632679"/>
      <geometry>
        <mesh filename="package://wx250s/meshes/wx250s_meshes/wx250s_6_wrist.stl" scale="0.001 0.001 0.001"/>
      </geometry>
      <material name="interbotix_black"/>
    </visual>
    <collision>
      <origin xyz="0 0 0" rpy="0 0 1.57079632679"/>
      <geometry>
        <mesh filename="package://wx250s/meshes/wx250s_meshes/wx250s_6_wrist.stl" scale="0.001 0.001 0.001"/>
      </geometry>
    </collision>
    <inertial>
      <origin xyz="0.04236 -0.000010663 0.010577" rpy="0 0 1.57079632679"/>
      <mass value="0.084957"/>
      <inertia ixx="0.00003082" iyy="0.00002822" izz="0.00003152" ixy="0.0000000191" ixz="0.0000000023" iyz="0.0000025481"/>
    </inertial>
  </link>

  <joint name="wrist_rotate" type="revolute">
    <parent link="wrist_link"/>
    <child link="gripper_link"/>
    <origin xyz="0.065 0 0" rpy="0 0 0"/>
    <axis xyz="1 0 0"/>
    <limit lower="-3.14158265359" upper="3.14158265359" effort="1" velocity="3.14159265359"/>
    <dynamics friction="0.1"/>
  </joint>

  <link name="gripper_link">
    <visual>
      <origin xyz="-0.02 0 0" rpy="0 0 1.57079632679"/>
      <geometry>
        <mesh filename="package://wx250s/meshes/wx250s_meshes/wx250s_7_gripper.stl" scale="0.001 0.001 0.001"/>
      </geometry>
      <material name="interbotix_black"/>
    </visual>
    <collision>
      <origin xyz="-0.02 0 0" rpy="0 0 1.57079632679"/>
      <geometry>
        <mesh filename="package://wx250s/meshes/wx250s_meshes/wx250s_7_gripper.stl" scale="0.001 0.001 0.001"/>
      </geometry>
    </collision>
    <inertial>
      <origin xyz="0.021631 0.0000002516 0.01141" rpy="0 0 1.57079632679"/>
      <mass value="0.072885"/>
      <inertia ixx="0.00002537" iyy="0.00001836" izz="0.00001674" ixy="0" ixz="0" iyz="0.000000434"/>
    </inertial>
  </link>

  <joint name="ee_arm" type="fixed">
    <parent link="gripper_link"/>
    <child link="ee_arm_link"/>
    <origin xyz="0.043 0 0" rpy="0 0 0"/>
  </joint>

  <link name="ee_arm_link">
    <inertial>
      <origin xyz="0 0 0" rpy="0 0 0"/>
      <mass value="0.001"/>
      <inertia ixx="0.001" iyy="0.001" izz="0.001" ixy="0" ixz="0" iyz="0"/>
    </inertial>
  </link>

  <joint name="gripper" type="continuous">
    <parent link="ee_arm_link"/>
    <child link="gripper_prop_link"/>
    <origin xyz="0.0055 0 0" rpy="0 0 0"/>
    <axis xyz="1 0 0"/>
    <limit effort="1" velocity="3.14159265359"/>
    <dynamics friction="0.1"/>
  </joint>

  <link name="gripper_prop_link">
    <visual>
      <origin xyz="-0.0685 0 0" rpy="0 0 1.57079632679"/>
      <geometry>
        <mesh filename="package://wx250s/meshes/wx250s_meshes/wx250s_8_gripper_prop.stl" scale="0.001 0.001 0.001"/>
      </geometry>
      <material name="interbotix_black"/>
    </visual>
    <collision>
      <origin xyz="-0.0685 0 0" rpy="0 0 1.57079632679"/>
      <geometry>
        <mesh filename="package://wx250s/meshes/wx250s_meshes/wx250s_8_gripper_prop.stl" scale="0.001 0.001 0.001"/>
      </geometry>
    </collision>
    <inertial>
      <origin xyz="0.000846 -0.0000016817 0.000042" rpy="0 0 1.57079632679"/>
      <mass value="0.00434"/>
      <inertia ixx="0.0000005923" iyy="0.0000011156" izz="0.0000005743" ixy="0" ixz="0.0000003195" iyz="-0.0000000004"/>
    </inertial>
  </link>

  <joint name="gripper_bar" type="fixed">
    <parent link="ee_arm_link"/>
    <child link="gripper_bar_link"/>
    <origin xyz="0 0 0" rpy="0 0 0"/>
  </joint>

  <link name="gripper_bar_link">
    <visual>
      <origin xyz="-0.063 0 0" rpy="0 0 1.57079632679"/>
      <geometry>
        <mesh filename="package://wx250s/meshes/wx250s_meshes/wx250s_9_gripper_bar.stl" scale="0.001 0.001 0.001"/>
      </geometry>
      <material name="interbotix_black"/>
    </visual>
    <collision>
      <origin xyz="-0.063 0 0" rpy="0 0 1.57079632679"/>
      <geometry>
        <mesh filename="package://wx250s/meshes/wx250s_meshes/wx250s_9_gripper_bar.stl" scale="0.001 0.001 0.001"/>
      </geometry>
    </collision>
    <inertial>
      <origin xyz="0.009687 0.0000008177 0.004962" rpy="0 0 1.57079632679"/>
      <mass value="0.034199"/>
      <inertia ixx="0.0000074125" iyy="0.00002843" izz="0.0000286" ixy="-0.0000000008" ixz="-0.0000000006" iyz="-0.0000013889"/>
    </inertial>
  </link>

  <joint name="ee_bar" type="fixed">
    <parent link="gripper_bar_link"/>
    <child link="fingers_link"/>
    <origin xyz="0.023 0 0" rpy="0 0 0"/>
  </joint>

  <link name="fingers_link">
    <inertial>
      <origin xyz="0 0 0" rpy="0 0 0"/>
      <mass value="0.001"/>
      <inertia ixx="0.001" iyy="0.001" izz="0.001" ixy="0" ixz="0" iyz="0"/>
    </inertial>
  </link>

  <joint name="left_finger" type="prismatic">
    <parent link="fingers_link"/>
    <child link="left_finger_link"/>
    <origin xyz="0 0 0" rpy="0 0 0"/>
    <axis xyz="0 1 0"/>
    <limit lower="0.015" upper="0.037" effort="5" velocity="1"/>
    <dynamics friction="0.1"/>
  </joint>

  <link name="left_finger_link">
    <visual>
      <origin xyz="0 0.005 0" rpy="3.14159265359 3.14159265359 0"/>
      <geometry>
        <mesh filename="package://wx250s/meshes/wx250s_meshes/wx250s_10_gripper_finger.stl" scale="0.001 0.001 0.001"/>
      </geometry>
      <material name="interbotix_black"/>
    </visual>
    <collision>
      <origin xyz="0 0.005 0" rpy="3.14159265359 3.14159265359 0"/>
      <geometry>
        <mesh filename="package://wx250s/meshes/wx250s_meshes/wx250s_10_gripper_finger.stl" scale="0.001 0.001 0.001"/>
      </geometry>
    </collision>
    <inertial>
      <origin xyz="0.013816 0 0" rpy="3.14159265359 3.14159265359 1.57079632679"/>
      <mass value="0.016246"/>
      <inertia ixx="0.000004731" iyy="0.0000015506" izz="0.0000037467" ixy="-0.000000456" ixz="0" iyz="0"/>
    </inertial>
  </link>

  <joint name="right_finger" type="prismatic">
    <parent link="fingers_link"/>
    <child link="right_finger_link"/>
    <origin xyz="0 0 0" rpy="0 0 0"/>
    <axis xyz="0 1 0"/>
    <limit lower="-0.037" upper="-0.015" effort="5" velocity="1"/>
    <dynamics friction="0.1"/>
  </joint>

  <link name="right_finger_link">
    <visual>
      <origin xyz="0 -0.005 0" rpy="0 3.14159265359 0"/>
      <geometry>
        <mesh filename="package://wx250s/meshes/wx250s_meshes/wx250s_10_gripper_finger.stl" scale="0.001 0.001 0.001"/>
      </geometry>
      <material name="interbotix_black"/>
    </visual>
    <collision>
      <origin xyz="0 -0.005 0" rpy="0 3.14159265359 0"/>
      <geometry>
        <mesh filename="package://wx250s/meshes/wx250s_meshes/wx250s_10_gripper_finger.stl" scale="0.001 0.001 0.001"/>
      </geometry>
    </collision>
    <inertial>
      <origin xyz="0.013816 0 0" rpy="0 3.14159265359 1.57079632679"/>
      <mass value="0.016246"/>
      <inertia ixx="0.000004731" iyy="0.0000015506" izz="0.0000037467" ixy="0.000000456" ixz="0" iyz="0"/>
    </inertial>
  </link>

  <joint name="ee_gripper" type="fixed">
    <parent link="fingers_link"/>
    <child link="ee_gripper_link"/>
    <origin xyz="0.027575 0 0" rpy="0 0 0"/>
  </joint>

  <link name="ee_gripper_link">
    <inertial>
      <origin xyz="0 0 0" rpy="0 0 0"/>
      <mass value="0.001"/>
      <inertia ixx="0.001" iyy="0.001" izz="0.001" ixy="0" ixz="0" iyz="0"/>
    </inertial>
  </link>
</robot>
